Workbook

Sheet Results
D1: 9-Tap Tour Inc. | H1: Total Payout:
H2: =I48 -> 0 | K2: # | L2: Mbr # | M2: Mbrship$ | N2: Adjust$ | O2: Total $
A3: Finish | B3: Winners | F3: Hdcp + Bonus | G3: Total Score | I3: Earnings
O4: =I4+I5-M4-N4 -> 0 | Q4: 0
B5: 1st Place | C5: =I4+I5 -> 0 | F5: $20 Progressive Pot
O6: =I6+I7-M6-N6 -> 0
B7: 2nd Place | C7: =I6+I7 -> 0 | F7: $20 Progressive Pot
O8: =I8+I9-M8-N8 -> 0
B9: 3rd Place | C9: =I8+I9 -> 0 | F9: $20 Progressive Pot
O10: =I10-M10-N10 -> 0
O11: =I11-M11-N11 -> 0
O12: =I12-M12-N12 -> 0
O13: =I13-M13-N13 -> 0
O14: =I14-M14-N14 -> 0
O15: =I15-M15-N15 -> 0
O16: =I16-M16-N16 -> 0
O17: =I17-M17-N17 -> 0
O18: =I18-M18-N18 -> 0
O19: =I19-M19-N19 -> 0
O20: =I20-M20-N20 -> 0
O21: =I21-M21-N21 -> 0
... O33: =I33-M33-N33 -> 0
A36: PROGRESSIVE POT TOTAL (for next Tournament)
A37: 9-TAP JACKPOT TOTAL (for next Tournament)
A38: 9-Tap Jackpot
A39: Scratch Pot - High Series
A40: 2nd/3rd
A41: Scratch Pot - High Game
A42: 2nd/3rd
A44: Progressive Pot | C44: =SUM(I5,I7,I9) -> 0 | D44: PRIZE FUND Entries | G44: x | H44: 35 | I44: =SUM((F44*H44)) -> 0
A45: 9-Tap Jackpot | C45: =SUM(I38) -> 0
A46: Scratch-Series/Game Pot | C46: =SUM(I39:I42) -> 0 | E46: Subtotal - Prize Fund | I46: =SUM(I44:I45) -> 0
A47: Side Pots | E47: Subtotal - Pots & Awards | I47: =SUM(C44:C48) -> 0
A48: Champion Shirt | E48: Total Paid-Out | I48: =SUM(I46:I47) -> 0
A51: HIGH GAME POTS
A52: SAT #1
A53: 2nd
A54: scores
A55: SAT #2
A56: 2nd
...

Sheet 1st
B2: =Results!A2 -> 0 | H2: =Results!A2 -> 0
B3: =Results!A4 -> 0 | E3: =Results!B4 -> 0 | H3: =Results!O4 -> 0
B4: =E3 -> 0
B5: sub total: | D5: =SpellNumber(H3) -> No Dollars and No Cents
B6: =Results!I4+Results!I5 -> 0
B7: Mbrship Paid:
B8: =Results!Q4-Results!M4 -> 0 | D8: =B3 -> 0 | E8: Place
B9: =H3 -> 0

Sheet 2nd
B2: =Results!A2 -> 0 | H2: =Results!A2 -> 0
B3: =Results!A6 -> 0 | E3: =Results!B6 -> 0 | H3: =Results!O6 -> 0
B4: =E3 -> 0
B5: sub total: | D5: =SpellNumber(H3) -> No Dollars and No Cents
B6: =Results!I6+Results!I7 -> 0
B7: Mbrship Paid:
B8: =Results!Q4-Results!M6 -> 0 | D8: =B3 -> 0 | E8: Place
B9: =H3 -> 0

Sheet 3rd
B2: =Results!A2 -> 0 | H2: =Results!A2 -> 0
B3: =Results!A8 -> 0 | E3: =Results!B8 -> 0 | H3: =Results!O8 -> 0
B4: =E3 -> 0
B5: sub total: | D5: =SpellNumber(H3) -> No Dollars and No Cents
B6: =Results!I8+Results!I9 -> 0
B7: Mbrship Paid:
B8: =Results!Q4-Results!M8 -> 0 | D8: =B3 -> 0 | E8: Place
B9: =H3 -> 0

Sheet 4th
B2: =Results!A2 -> 0 | H2: =Results!A2 -> 0
B3: =Results!A10 -> 0 | E3: =Results!B10 -> 0 | H3: =Results!O10 -> 0
B4: =E3 -> 0
B5: sub total: | D5: =SpellNumber(H3) -> No Dollars and No Cents
B6: =Results!I10 -> 0
B7: Mbrship Paid:
B8: =Results!Q4-Results!M10 -> 0 | D8: =B3 -> 0 | E8: Place
B9: =H3 -> 0

Sheet 5th
B2: =Results!A2 -> 0 | H2: =Results!A2 -> 0
B3: =Results!A11 -> 0 | E3: =Results!B11 -> 0 | H3: =Results!O11 -> 0
B4: =E3 -> 0
B5: sub total: | D5: =SpellNumber(H3) -> No Dollars and No Cents
B6: =Results!I11 -> 0
B7: Mbrship Paid:
B8: =Results!Q4-Results!M11 -> 0 | D8: =B3 -> 0 | E8: Place
B9: =H3 -> 0

Sheet 6th
B2: =Results!A2 -> 0 | H2: =Results!A2 -> 0
B3: =Results!A12 -> 0 | E3: =Results!B12 -> 0 | H3: =Results!O12 -> 0
B4: =E3 -> 0
B5: sub total: | D5: =SpellNumber(H3) -> No Dollars and No Cents
B6: =Results!I12 -> 0
B7: Mbrship Paid:
B8: =Results!Q4-Results!M12 -> 0 | D8: =B3 -> 0 | E8: Place
B9: =H3 -> 0

Sheet 7th
B2: =Results!A2 -> 0 | H2: =Results!A2 -> 0
B3: =Results!A13 -> 0 | E3: =Results!B13 -> 0 | H3: =Results!O13 -> 0
B4: =E3 -> 0
B5: sub total: | D5: =SpellNumber(H3) -> No Dollars and No Cents
B6: =Results!I13 -> 0
B7: Mbrship Paid:
B8: =Results!Q4-Results!M13 -> 0 | D8: =B3 -> 0 | E8: Place
B9: =H3 -> 0

Sheet 8th
B2: =Results!A2 -> 0 | H2: =Results!A2 -> 0
B3: =Results!A14 -> 0 | E3: =Results!B14 -> 0 | H3: =Results!O14 -> 0
B4: =E3 -> 0
B5: sub total: | D5: =SpellNumber(H3) -> No Dollars and No Cents
B6: =Results!I14 -> 0
B7: Mbrship Paid:
B8: =Results!Q4-Results!M14 -> 0 | D8: =B3 -> 0 | E8: Place
B9: =H3 -> 0

Sheet 9th
B2: =Results!A2 -> 0 | H2: =Results!A2 -> 0
B3: =Results!A15 -> 0 | E3: =Results!B15 -> 0 | H3: =Results!O15 -> 0
B4: =E3 -> 0
B5: sub total: | D5: =SpellNumber(H3) -> No Dollars and No Cents
B6: =Results!I15 -> 0
B7: Mbrship Paid:
B8: =Results!Q4-Results!M15 -> 0 | D8: =B3 -> 0 | E8: Place
B9: =H3 -> 0

Sheet 10th
B2: =Results!A2 -> 0 | H2: =Results!A2 -> 0
B3: =Results!A16 -> 0 | E3: =Results!B16 -> 0 | H3: =Results!O16 -> 0
B4: =E3 -> 0
B5: sub total: | D5: =SpellNumber(H3) -> No Dollars and No Cents
B6: =Results!I16 -> 0
B7: Mbrship Paid:
B8: =Results!Q4-Results!M16 -> 0 | D8: =B3 -> 0 | E8: Place
B9: =H3 -> 0

Sheet 11th
B2: =Results!A2 -> 0 | H2: =Results!A2 -> 0
B3: =Results!A17 -> 0 | E3: =Results!B17 -> 0 | H3: =Results!O17 -> 0
B4: =E3 -> 0
B5: sub total: | D5: =SpellNumber(H3) -> No Dollars and No Cents
B6: =Results!I17 -> 0
B7: Mbrship Paid:
B8: =Results!Q4-Results!M17 -> 0 | D8: =B3 -> 0 | E8: Place
B9: =H3 -> 0

Sheet 12th
B2: =Results!A2 -> 0 | H2: =Results!A2 -> 0
B3: =Results!A18 -> 0 | E3: =Results!B18 -> 0 | H3: =Results!O18 -> 0
B4: =E3 -> 0
B5: sub total: | D5: =SpellNumber(H3) -> No Dollars and No Cents
B6: =Results!I18 -> 0
B7: Mbrship Paid:
B8: =Results!Q4-Results!M18 -> 0 | D8: =B3 -> 0 | E8: Place
B9: =H3 -> 0

Sheet 13th
B2: =Results!A2 -> 0 | H2: =Results!A2 -> 0
B3: =Results!A19 -> 0 | E3: =Results!B19 -> 0 | H3: =Results!O19 -> 0
B4: =E3 -> 0
B5: sub total: | D5: =SpellNumber(H3) -> No Dollars and No Cents
B6: =Results!I19 -> 0
B7: Mbrship Paid:
B8: =Results!Q4-Results!M19 -> 0 | D8: =B3 -> 0 | E8: Place
B9: =H3 -> 0

Sheet 14th
B2: =Results!A2 -> 0 | H2: =Results!A2 -> 0
B3: =Results!A20 -> 0 | E3: =Results!B20 -> 0 | H3: =Results!O20 -> 0
B4: =E3 -> 0
B5: sub total: | D5: =SpellNumber(H3) -> No Dollars and No Cents
B6: =Results!I20 -> 0
B7: Mbrship Paid:
B8: =Results!Q4-Results!M20 -> 0 | D8: =B3 -> 0 | E8: Place
B9: =H3 -> 0

Sheet 15th
B2: =Results!A2 -> 0 | H2: =Results!A2 -> 0
B3: =Results!A21 -> 0 | E3: =Results!B21 -> 0 | H3: =Results!O21 -> 0
B4: =E3 -> 0
B5: sub total: | D5: =SpellNumber(H3) -> No Dollars and No Cents
B6: =Results!I21 -> 0
B7: Mbrship Paid:
B8: =Results!Q4-Results!M21 -> 0 | D8: =B3 -> 0 | E8: Place
B9: =H3 -> 0

Sheet 16th
B2: =Results!A2 -> 0 | H2: =Results!A2 -> 0
B3: =Results!A22 -> 0 | E3: =Results!B22 -> 0 | H3: =Results!O22 -> 0
B4: =E3 -> 0
B5: sub total: | D5: =SpellNumber(H3) -> No Dollars and No Cents
B6: =Results!I22 -> 0
B7: Mbrship Paid:
B8: =Results!Q4-Results!M22 -> 0 | D8: =B3 -> 0 | E8: Place
B9: =H3 -> 0

Sheet 17th
B2: =Results!A2 -> 0 | H2: =Results!A2 -> 0
B3: =Results!A23 -> 0 | E3: =Results!B23 -> 0 | H3: =Results!O23 -> 0
B4: =E3 -> 0
B5: sub total: | D5: =SpellNumber(H3) -> No Dollars and No Cents
B6: =Results!I23 -> 0
B7: Mbrship Paid:
B8: =Results!Q4-Results!M23 -> 0 | D8: =B3 -> 0 | E8: Place
B9: =H3 -> 0

Sheet 18th
B2: =Results!A2 -> 0 | H2: =Results!A2 -> 0
B3: =Results!A24 -> 0 | E3: =Results!B24 -> 0 | H3: =Results!O24 -> 0
B4: =E3 -> 0
B5: sub total: | D5: =SpellNumber(H3) -> No Dollars and No Cents
B6: =Results!I24 -> 0
B7: Mbrship Paid:
B8: =Results!Q4-Results!M24 -> 0 | D8: =B3 -> 0 | E8: Place
B9: =H3 -> 0

Sheet 19th
B2: =Results!A2 -> 0 | H2: =Results!A2 -> 0
B3: =Results!A25 -> 0 | E3: =Results!B25 -> 0 | H3: =Results!O25 -> 0
B4: =E3 -> 0
B5: sub total: | D5: =SpellNumber(H3) -> No Dollars and No Cents
B6: =Results!I25 -> 0
B7: Mbrship Paid:
B8: =Results!Q4-Results!M25 -> 0 | D8: =B3 -> 0 | E8: Place
B9: =H3 -> 0

Sheet 20th
B2: =Results!A2 -> 0 | H2: =Results!A2 -> 0
B3: =Results!A26 -> 0 | E3: =Results!B26 -> 0 | H3: =Results!O26 -> 0
B4: =E3 -> 0
B5: sub total: | D5: =SpellNumber(H3) -> No Dollars and No Cents
B6: =Results!I26 -> 0
B7: Mbrship Paid:
B8: =Results!Q4-Results!M26 -> 0 | D8: =B3 -> 0 | E8: Place
B9: =H3 -> 0

Sheet 21st
B2: =Results!A2 -> 0 | H2: =Results!A2 -> 0
B3: =Results!A27 -> 0 | E3: =Results!B27 -> 0 | H3: =Results!O27 -> 0
B4: =E3 -> 0
B5: sub total: | D5: =SpellNumber(H3) -> No Dollars and No Cents
B6: =Results!I27 -> 0
B7: Mbrship Paid:
B8: =Results!Q4-Results!M27 -> 0 | D8: =B3 -> 0 | E8: Place
B9: =H3 -> 0

Sheet 22nd
B2: =Results!A2 -> 0 | H2: =Results!A2 -> 0
B3: =Results!A28 -> 0 | E3: =Results!B28 -> 0 | H3: =Results!O28 -> 0
B4: =E3 -> 0
B5: sub total: | D5: =SpellNumber(H3) -> No Dollars and No Cents
B6: =Results!I28 -> 0
B7: Mbrship Paid:
B8: =Results!Q4-Results!M28 -> 0 | D8: =B3 -> 0 | E8: Place
B9: =H3 -> 0

Sheet 23rd
B2: =Results!A2 -> 0 | H2: =Results!A2 -> 0
B3: =Results!A29 -> 0 | E3: =Results!B29 -> 0 | H3: =Results!O29 -> 0
B4: =E3 -> 0
B5: sub total: | D5: =SpellNumber(H3) -> No Dollars and No Cents
B6: =Results!I29 -> 0
B7: Mbrship Paid:
B8: =Results!Q4-Results!M29 -> 0 | D8: =B3 -> 0 | E8: Place
B9: =H3 -> 0

Sheet 24th
B2: =Results!A2 -> 0 | H2: =Results!A2 -> 0
B3: =Results!A30 -> 0 | E3: =Results!B30 -> 0 | H3: =Results!O30 -> 0
B4: =E3 -> 0
B5: sub total: | D5: =SpellNumber(H3) -> No Dollars and No Cents
B6: =Results!I30 -> 0
B7: Mbrship Paid:
B8: =Results!Q4-Results!M30 -> 0 | D8: =B3 -> 0 | E8: Place
B9: =H3 -> 0

Sheet 25th
B2: =Results!A2 -> 0 | H2: =Results!A2 -> 0
B3: =Results!A31 -> 0 | E3: =Results!B31 -> 0 | H3: =Results!O31 -> 0
B4: =E3 -> 0
B5: sub total: | D5: =SpellNumber(H3) -> No Dollars and No Cents
B6: =Results!I31 -> 0
B7: Mbrship Paid:
B8: =Results!Q4-Results!M31 -> 0 | D8: =B3 -> 0 | E8: Place
B9: =H3 -> 0

Sheet 26th
B2: =Results!A2 -> 0 | H2: =Results!A2 -> 0
B3: =Results!A32 -> 0 | E3: =Results!B32 -> 0 | H3: =Results!O32 -> 0
B4: =E3 -> 0
B5: sub total: | D5: =SpellNumber(H3) -> No Dollars and No Cents
B6: =Results!I32 -> 0
B7: Mbrship Paid:
B8: =Results!Q4-Results!M32 -> 0 | D8: =B3 -> 0 | E8: Place
B9: =H3 -> 0

Sheet 27th
B2: =Results!A2 -> 0 | H2: =Results!A2 -> 0
B3: =Results!A33 -> 0 | E3: =Results!B33 -> 0 | H3: =Results!O33 -> 0
B4: =E3 -> 0
B5: sub total: | D5: =SpellNumber(H3) -> No Dollars and No Cents
B6: =Results!I33 -> 0
B7: Mbrship Paid:
B8: =Results!Q4-Results!M33 -> 0 | D8: =B3 -> 0 | E8: Place
B9: =H3 -> 0

Sheet 28th
B2: =Results!A2 -> 0 | H2: =Results!A2 -> 0
B3: =Results!#REF! -> #REF! | E3: =Results!#REF! -> #REF! | H3: =Results!#REF! -> #REF!
B4: =E3 -> #REF!
B5: sub total: | D5: =SpellNumber(H3) -> #VALUE!
B6: =Results!#REF! -> #REF!
B7: Mbrship Paid:
B8: =Results!Q4-Results!#REF! -> #REF! | D8: =B3 -> #REF! | E8: Place
B9: =H3 -> #REF!

Sheet 29th
B2: =Results!A2 -> 0 | H2: =Results!A2 -> 0
B3: =Results!#REF! -> #REF! | E3: =Results!#REF! -> #REF! | H3: =Results!#REF! -> #REF!
B4: =E3 -> #REF!
B5: sub total: | D5: =SpellNumber(H3) -> #VALUE!
B6: =Results!#REF! -> #REF!
B7: Mbrship Paid:
B8: =Results!Q4-Results!#REF! -> #REF! | D8: =B3 -> #REF! | E8: Place
B9: =H3 -> #REF!

Sheet 30th
B2: =Results!A2 -> 0 | H2: =Results!A2 -> 0
B3: =Results!#REF! -> #REF! | E3: =Results!#REF! -> #REF! | H3: =Results!#REF! -> #REF!
B4: =E3 -> #REF!
B5: sub total: | D5: =SpellNumber(H3) -> #VALUE!
B6: =Results!#REF! -> #REF!
B7: Mbrship Paid:
B8: =Results!Q4-Results!#REF! -> #REF! | D8: =B3 -> #REF! | E8: Place
B9: =H3 -> #REF!

Sheet 31st
B2: =Results!A2 -> 0 | H2: =Results!A2 -> 0
B3: =Results!#REF! -> #REF! | E3: =Results!#REF! -> #REF! | H3: =Results!#REF! -> #REF!
B4: =E3 -> #REF!
B5: sub total: | D5: =SpellNumber(H3) -> #VALUE!
B6: =Results!#REF! -> #REF!
B7: Mbrship Paid:
B8: =Results!Q4-Results!#REF! -> #REF! | D8: =B3 -> #REF! | E8: Place
B9: =H3 -> #REF!

Sheet 32nd
B2: =Results!A2 -> 0 | H2: =Results!A2 -> 0
B3: =Results!#REF! -> #REF! | E3: =Results!#REF! -> #REF! | H3: =Results!#REF! -> #REF!
B4: =E3 -> #REF!
B5: sub total: | D5: =SpellNumber(H3) -> #VALUE!
B6: =Results!#REF! -> #REF!
B7: Mbrship Paid:
B8: =Results!Q4-Results!#REF! -> #REF! | D8: =B3 -> #REF! | E8: Place
B9: =H3 -> #REF!

Sheet 33rd
B2: =Results!A2 -> 0 | H2: =Results!A2 -> 0
B3: =Results!#REF! -> #REF! | E3: =Results!#REF! -> #REF! | H3: =Results!#REF! -> #REF!
B4: =E3 -> #REF!
B5: sub total: | D5: =SpellNumber(H3) -> #VALUE!
B6: =Results!#REF! -> #REF!
B7: Mbrship Paid:
B8: =Results!Q4-Results!#REF! -> #REF! | D8: =B3 -> #REF! | E8: Place
B9: =H3 -> #REF!

Sheet 34th
B2: =Results!A2 -> 0 | H2: =Results!A2 -> 0
B3: =Results!#REF! -> #REF! | E3: =Results!#REF! -> #REF! | H3: =Results!#REF! -> #REF!
B4: =E3 -> #REF!
B5: sub total: | D5: =SpellNumber(H3) -> #VALUE!
B6: =Results!#REF! -> #REF!
B7: Mbrship Paid:
B8: =Results!Q4-Results!#REF! -> #REF! | D8: =B3 -> #REF! | E8: Place
B9: =H3 -> #REF!

Sheet 35th
B2: =Results!A2 -> 0 | H2: =Results!A2 -> 0
B3: =Results!#REF! -> #REF! | E3: =Results!#REF! -> #REF! | H3: =Results!#REF! -> #REF!
B4: =E3 -> #REF!
B5: sub total: | D5: =SpellNumber(H3) -> #VALUE!
B6: =Results!#REF! -> #REF!
B7: Mbrship Paid:
B8: =Results!Q4-Results!#REF! -> #REF! | D8: =B3 -> #REF! | E8: Place
B9: =H3 -> #REF!

Sheet 36th
B2: =Results!A2 -> 0 | H2: =Results!A2 -> 0
B3: =Results!#REF! -> #REF! | E3: =Results!#REF! -> #REF! | H3: =Results!#REF! -> #REF!
B4: =E3 -> #REF!
B5: sub total: | D5: =SpellNumber(H3) -> #VALUE!
B6: =Results!#REF! -> #REF!
B7: Mbrship Paid:
B8: =Results!Q4-Results!#REF! -> #REF! | D8: =B3 -> #REF! | E8: Place
B9: =H3 -> #REF!

Sheet 37th
B2: =Results!A2 -> 0 | H2: =Results!A2 -> 0
B3: =Results!#REF! -> #REF! | E3: =Results!#REF! -> #REF! | H3: =Results!#REF! -> #REF!
B4: =E3 -> #REF!
B5: sub total: | D5: =SpellNumber(H3) -> #VALUE!
B6: =Results!#REF! -> #REF!
B7: Mbrship Paid:
B8: =Results!Q4-Results!#REF! -> #REF! | D8: =B3 -> #REF! | E8: Place
B9: =H3 -> #REF!

Sheet 38th
B2: =Results!A2 -> 0 | H2: =Results!A2 -> 0
B3: =Results!#REF! -> #REF! | E3: =Results!#REF! -> #REF! | H3: =Results!#REF! -> #REF!
B4: =E3 -> #REF!
B5: sub total: | D5: =SpellNumber(H3) -> #VALUE!
B6: =Results!#REF! -> #REF!
B7: Mbrship Paid:
B8: =Results!Q4-Results!#REF! -> #REF! | D8: =B3 -> #REF! | E8: Place
B9: =H3 -> #REF!

Sheet 39th
B2: =Results!A2 -> 0 | H2: =Results!A2 -> 0
B3: =Results!#REF! -> #REF! | E3: =Results!#REF! -> #REF! | H3: =Results!#REF! -> #REF!
B4: =E3 -> #REF!
B5: sub total: | D5: =SpellNumber(H3) -> #VALUE!
B6: =Results!#REF! -> #REF!
B7: Mbrship Paid:
B8: =Results!Q4-Results!#REF! -> #REF! | D8: =B3 -> #REF! | E8: Place
B9: =H3 -> #REF!

Sheet 40th
B2: =Results!A2 -> 0 | H2: =Results!A2 -> 0
B3: =Results!#REF! -> #REF! | E3: =Results!#REF! -> #REF! | H3: =Results!#REF! -> #REF!
B4: =E3 -> #REF!
B5: sub total: | D5: =SpellNumber(H3) -> #VALUE!
B6: =Results!#REF! -> #REF!
B7: Mbrship Paid:
B8: =Results!Q4-Results!#REF! -> #REF! | D8: =B3 -> #REF! | E8: Place
B9: =H3 -> #REF!

Sheet 41st
B2: =Results!A2 -> 0 | H2: =Results!A2 -> 0
B3: =Results!#REF! -> #REF! | E3: =Results!#REF! -> #REF! | H3: =Results!#REF! -> #REF!
B4: =E3 -> #REF!
B5: sub total: | D5: =SpellNumber(H3) -> #VALUE!
B6: =Results!#REF! -> #REF!
B7: Mbrship Paid:
B8: =Results!Q4-Results!#REF! -> #REF! | D8: =B3 -> #REF! | E8: Place
B9: =H3 -> #REF!

Sheet 42nd
B2: =Results!A2 -> 0 | H2: =Results!A2 -> 0
B3: =Results!#REF! -> #REF! | E3: =Results!#REF! -> #REF! | H3: =Results!#REF! -> #REF!
B4: =E3 -> #REF!
B5: sub total: | D5: =SpellNumber(H3) -> #VALUE!
B6: =Results!#REF! -> #REF!
B7: Mbrship Paid:
B8: =Results!Q4-Results!#REF! -> #REF! | D8: =B3 -> #REF! | E8: Place
B9: =H3 -> #REF!

Sheet 43rd
B2: =Results!A2 -> 0 | H2: =Results!A2 -> 0
B3: =Results!#REF! -> #REF! | E3: =Results!#REF! -> #REF! | H3: =Results!#REF! -> #REF!
B4: =E3 -> #REF!
B5: sub total: | D5: =SpellNumber(H3) -> #VALUE!
B6: =Results!#REF! -> #REF!
B7: Mbrship Paid:
B8: =Results!Q4-Results!#REF! -> #REF! | D8: =B3 -> #REF! | E8: Place
B9: =H3 -> #REF!

Sheet 44th
B2: =Results!A2 -> 0 | H2: =Results!A2 -> 0
B3: =Results!#REF! -> #REF! | E3: =Results!#REF! -> #REF! | H3: =Results!#REF! -> #REF!
B4: =E3 -> #REF!
B5: sub total: | D5: =SpellNumber(H3) -> #VALUE!
B6: =Results!#REF! -> #REF!
B7: Mbrship Paid:
B8: =Results!Q4-Results!#REF! -> #REF! | D8: =B3 -> #REF! | E8: Place
B9: =H3 -> #REF!

Sheet 45th
B2: =Results!A2 -> 0 | H2: =Results!A2 -> 0
B3: =Results!#REF! -> #REF! | E3: =Results!#REF! -> #REF! | H3: =Results!#REF! -> #REF!
B4: =E3 -> #REF!
B5: sub total: | D5: =SpellNumber(H3) -> #VALUE!
B6: =Results!#REF! -> #REF!
B7: Mbrship Paid:
B8: =Results!Q4-Results!#REF! -> #REF! | D8: =B3 -> #REF! | E8: Place
B9: =H3 -> #REF!

Sheet 46th
B2: =Results!A2 -> 0 | H2: =Results!A2 -> 0
B3: =Results!#REF! -> #REF! | E3: =Results!#REF! -> #REF! | H3: =Results!#REF! -> #REF!
B4: =E3 -> #REF!
B5: sub total: | D5: =SpellNumber(H3) -> #VALUE!
B6: =Results!#REF! -> #REF!
B7: Mbrship Paid:
B8: =Results!Q4-Results!#REF! -> #REF! | D8: =B3 -> #REF! | E8: Place
B9: =H3 -> #REF!

Sheet 47th
B2: =Results!A2 -> 0 | H2: =Results!A2 -> 0
B3: =Results!#REF! -> #REF! | E3: =Results!#REF! -> #REF! | H3: =Results!#REF! -> #REF!
B4: =E3 -> #REF!
B5: sub total: | D5: =SpellNumber(H3) -> #VALUE!
B6: =Results!#REF! -> #REF!
B7: Mbrship Paid:
B8: =Results!Q4-Results!#REF! -> #REF! | D8: =B3 -> #REF! | E8: Place
B9: =H3 -> #REF!

Sheet 48th
B2: =Results!A2 -> 0 | H2: =Results!A2 -> 0
B3: =Results!#REF! -> #REF! | E3: =Results!#REF! -> #REF! | H3: =Results!#REF! -> #REF!
B4: =E3 -> #REF!
B5: sub total: | D5: =SpellNumber(H3) -> #VALUE!
B6: =Results!#REF! -> #REF!
B7: Mbrship Paid:
B8: =Results!Q4-Results!#REF! -> #REF! | D8: =B3 -> #REF! | E8: Place
B9: =H3 -> #REF!

Sheet 49th
B2: =Results!A2 -> 0 | H2: =Results!A2 -> 0
B3: =Results!#REF! -> #REF! | E3: =Results!#REF! -> #REF! | H3: =Results!#REF! -> #REF!
B4: =E3 -> #REF!
B5: sub total: | D5: =SpellNumber(H3) -> #VALUE!
B6: =Results!#REF! -> #REF!
B7: Mbrship Paid:
B8: =Results!Q4-Results!#REF! -> #REF! | D8: =B3 -> #REF! | E8: Place
B9: =H3 -> #REF!

Sheet 50th
B2: =Results!A2 -> 0 | H2: =Results!A2 -> 0
B3: =Results!#REF! -> #REF! | E3: =Results!#REF! -> #REF! | H3: =Results!#REF! -> #REF!
B4: =E3 -> #REF!
B5: sub total: | D5: =SpellNumber(H3) -> #VALUE!
B6: =Results!#REF! -> #REF!
B7: Mbrship Paid:
B8: =Results!Q4-Results!#REF! -> #REF! | D8: =B3 -> #REF! | E8: Place
B9: =H3 -> #REF!
